Traceback (most recent call last):
  File "/home/vm-admin/WiFiTracker/Service/Acquisition.py", line 101, in main
    time.sleep(5)
KeyboardInterrupt

During handling of the above exception, another exception occurred:

Traceback (most recent call last):
  File "/home/vm-admin/WiFiTracker/Service/Acquisition.py", line 108, in <module>
    aq.main()
  File "/home/vm-admin/WiFiTracker/Service/Acquisition.py", line 103, in main
    raise Exception("Program interrupted")
Exception: Program interrupted
